Workbook

Sheet Inputs
A1: Stock question
A2: Monthly stock purchase | B2: 300000
A4: Stock Rotation Cycle Length (in days) | B4: 45
A5: Stock Rotation Cycle Length (in months) | B5: =B4/30 -> 1.5
A6: Stock Rotation Cycle Length (in Years) | B6: =365/B4 -> 8.1111111
A8: Discount received from Supplier
A9: A) Bulk discount (%) | B9: 5
A10: B) Scheme Discount (%) | B10: 3
A11: C) Cash Discount (%) | B11: 2
A12: Is price increased from last year if yes then how much (%)/ kya maal mahenga aa raha hai | B12: 5
A15: Sales question
A16: Monthly Sales | B16: 100000
A17: Profit Margin (%) | B17: 20
A18: Season Uplift (%) | B18: 20
A19: Number of months for season | B19: 3
A22: Competition Question
A23: Daily walk in | B23: 20
A24: Average bill value | B24: 2000
A25: Customer left or go to competitor due to low stock | B25: 10
A27: Credit/ outstanding Question
A28: For how many days you give credit | B28: 20
A29: total udhari/ outstanding amount (receivable) | B29: 50000
A30: Is udhari Stable or increasing | B30: yes/no
A32: Fixed Expenses Questions
A33: Rent | B33: 10000
A34: Electricity | B34: 500
A35: Salaries | B35: 20000
A36: Expected increase every year (%) | B36: 10
A38: Inflation Questions
A39: Every year inflation increase | B39: 0.07
A41: Loan Questions
A42: Loan Amount | B42: 200000
A43: Tenure in years | B43: 5
A44: Tenure in months | B44: =B43*12 -> 60
A45: IRR (%) | B45: 24
A46: EMI (Monthly) | B46: 5753.59
A47: Total Repayment | B47: =B46*B44 -> 345215.4
A48: Cash Cycle Delay (days) | B48: 15
A49: Stock purchase from loan | B49: =B42 -> 200000

Sheet Cost_of_Delay
A1: Metric | B1: Value
A2: Competitor Loss
A3: Lost Sales Per Month due to competition | B3: =(Inputs!B25*Inputs!B24) -> 20000
A4: Lost Profit Per Month | B4: =B3 * Inputs!B17 / 100 -> 4000
A6: Supplier discount
A7: Monthly stock Purchase | B7: =Inputs!B2 -> 300000
A8: Total Bulk discount | B8: =B7*(Inputs!B9+Inputs!B10+Inputs!B11)% -> 30000
A9: Bulk discount (Stock turnover per month) | B9: =B8*Inputs!B6/12 -> 20277.778
A10: Bulk discount (Stock turnover per year) | B10: =B9*12 -> 243333.33
A12: Seasonal loss
A13: Monthly sales | B13: =Inputs!B16 -> 100000
A14: Season uplift | B14: =Inputs!B18 -> 20
A15: Number of months of season | B15: =Inputs!B19 -> 3
A16: Sales loss in season | B16: =(B13*B14%)*B15 -> 60000
A17: Loss profit in season | B17: =B16*Inputs!B17% -> 12000
A18: Average per month season loss | B18: =B17/12 -> 1000
A20: Fixed expense increase cost
A21: Rent | B21: =Inputs!B33 -> 10000
A22: Electricity | B22: =Inputs!B34 -> 500
A23: Salaries | B23: =Inputs!B35 -> 20000
A24: Expected increase in prices by next year(%) | B24: =Inputs!B36 -> 10
A25: Total expense increase per month by next year | B25: =(B21+B22+B23)*B24% -> 3050
A27: Inflation
A28: Inflation increasing every year | B28: 0.07
A29: Sales per month | B29: =Inputs!B16 -> 100000
A30: Net profit Margin | B30: =Inputs!B17 -> 20
A31: Profit per month today | B31: =B29*B30% -> 20000
A32: After Adjusting Inflation | B32: =B31*(100%-B28) -> 18600
A33: Net loss after adjusting Inflation per month | B33: =B31-B32 -> 1400
A35: Credit outstanding loss
A36: Monthly sales | B36: =Inputs!B16 -> 100000
A37: Ideadl udhari days | B37: 7
A38: Ideal udhari amount | B38: =B36/30*7 -> 23333.333
A39: Actual udhari amount | B39: =Inputs!B29 -> 50000
A40: Excess udhari | B40: =B39-B38 -> 26666.667
A41: business loss due to udhari | B41: =B40*(Inputs!B17%) -> 5333.3333
A42: Interest loss due to udhari | B42: =B40*1% -> 266.66667
A43: Total loss due to udhari | B43: =B41+B42 -> 5600
A45: Supplier increasing stock price
A46: Monthly stock purchase | B46: =Inputs!B2 -> 300000
...

Sheet ROI
A1: Metric | B1: Value
A2: Normal months without season | B2: =12-Inputs!B19 -> 9
A3: Season months per year | B3: =Inputs!B19 -> 3
A4: Expected Normal Sales Increase with loan | B4: =Inputs!B49*Inputs!B6/12 -> 135185.19
A5: Expected Season Sales Increase with loan | B5: =B4 * Inputs!B18% -> 27037.037
A6: Total increase in sales in each season months with loan | B6: =B4+B5 -> 162222.22
A7: Total sales in all season months with loan | B7: =B6*B3 -> 486666.67
A8: Total sale for normal months without season with loan | B8: =B4*B2 -> 1216666.7
A9: combined yearly sale (season and normal months) | B9: =B7+B8 -> 1703333.3
A10: Average combined monthly sale | B10: =B9/12 -> 141944.44
A12: Expected profit Increase of each normal month | B12: =B4 * Inputs!B17% -> 27037.037
A13: Expected profit Increase of each month of season | B13: =B6*Inputs!B17/100 -> 32444.444
A14: Expected Normal Profit Increase per year | B14: =B12*(12-Inputs!B19) -> 243333.33
A15: Expected season Profit Increase per year | B15: =B13*Inputs!B19 -> 97333.333
A16: Total Profit increase for 12 months | B16: =B14+B15 -> 340666.67
A17: Average profit increase per months | B17: =B16/12 -> 28388.889
A20: Total discount
A21: Purchase from loan | B21: =Inputs!B49 -> 200000
A22: Total discount | B22: =B21*(Inputs!B9+Inputs!B10+Inputs!B11)% -> 20000
A23: Total discount (Stock turnover per month) | B23: =B22*Inputs!B6/12 -> 13518.519
A24: Total discount (Stock turnover per year) | B24: =B23*12 -> 162222.22
A26: Competitor Loss
A27: Lost Sales Per Month due to competition | B27: =(Inputs!B25*Inputs!B24) -> 20000
A28: Lost Profit Per Month | B28: =B27 * Inputs!B17 / 100 -> 4000
A30: Cash cycle improvement | B30: monthly | C30: yearly
A31: Per month old sale | B31: =Inputs!B16 -> 100000 | C31: =B31*12 -> 1200000
A32: per month New sale | B32: =B4 -> 135185.19 | C32: =B32*(12-Inputs!B19) -> 1216666.7
A33: Total sales in season (per month) | B33: =B6 -> 162222.22 | C33: =B33*Inputs!B19 -> 486666.67
A34: old profits | B34: =B31*Inputs!B17/100 -> 20000 | C34: =C31*Inputs!B17/100 -> 240000
A35: Expected Norma month Profit Increase | B35: =B12 -> 27037.037 | C35: =B14 -> 243333.33
A36: Expected season months Profit Increase | B36: =B13 -> 32444.444 | C36: =B15 -> 97333.333
A38: Total Profit increase for 12 months (old+new) | C38: =C34+C35+C36 -> 580666.67
A39: Average total profit increase for 12 months monthly (Old + New) | C39: =C38/12 -> 48388.889
A41: cash cycle improvement (5)% | C41: =C39*5% -> 2419.4444
A42: cash cycle improvement (10)% | C42: =C39*10% -> 4838.8889
A45: Total profit per month | B45: =B17+B23+B28+C42 -> 50746.296
A46: Total profit for year | B46: =B45*12 -> 608955.56
A47: Annual ROI | B47: =B46 / (Inputs!B47)*100 -> 176.39872
A48: Payback Period (Months) | B48: =Inputs!B47 / B45 -> 6.8027704
